<?xml version="1.0" ?>
<!-- =================================================================================== -->
<!-- |    This document was autogenerated by xacro from robots/herb.urdf.xacro         | -->
<!-- |    EDITING THIS FILE BY HAND IS NOT RECOMMENDED                                 | -->
<!-- =================================================================================== -->
<robot name="herb" xmlns:xacro="http://www.ros.org/wiki/xacro">
  <!-- Fixed Transforms -->
  <link name="base_footprint">
    <inertial>
      <origin rpy="0 0 0" xyz="0 0 0"/>
      <mass value="0.1"/>
      <inertia ixx="1" ixy="0" ixz="0" iyy="1" iyz="0" izz="1"/>
    </inertial>
  </link>
  <link name="herb_frame">
    <!--check inertias and mass-->
    <inertial>
      <origin rpy="0 0 0" xyz="0 0 0"/>
      <mass value="106.25"/>
      <inertia ixx="22.3955" ixy="-0.2746" ixz="-0.0999" iyy="5.9126" iyz="5.1995" izz="20.4410"/>
    </inertial>
    <visual>
      <origin rpy="1.57075 0 3.141592" xyz="0 0 0"/>
      <geometry>
        <mesh filename="package://herb_description/meshes/base/herb_frame.STL"/>
      </geometry>
      <material name="">
        <color rgba="0.3 0 0 1"/>
      </material>
    </visual>
    <collision>
      <origin rpy="1.57075 0 -1.57075" xyz="0 0 0"/>
      <geometry>
        <mesh filename="package://herb_description/meshes/base/herb_frame_collision.STL"/>
      </geometry>
    </collision>
  </link>
  <link name="neobotix_base">
    <!--check inertias and mass-->
    <inertial>
      <origin rpy="0 0 0" xyz="0 -0.074086 -1.101244"/>
      <mass value="80"/>
      <inertia ixx="9.25557" ixy="0.00548" ixz="0.00573" iyy="7.60171" iyz="1.02901" izz="9.76036"/>
    </inertial>
    <visual>
      <origin rpy="0 0 0" xyz="0 0 0"/>
      <geometry>
        <mesh filename="package://herb_description/meshes/base/herb_neobotix_base.STL"/>
      </geometry>
      <material name="">
        <color rgba="0.3 0.3 0.3 1"/>
      </material>
    </visual>
    <collision>
      <origin rpy="1.57075 0 1.57075" xyz="0 0 0"/>
      <geometry>
        <mesh filename="package://herb_description/meshes/base/herb_neobotix_base_collision.STL"/>
      </geometry>
    </collision>
  </link>
  <joint name="root_to_frame" type="fixed">
    <origin rpy="0 0 -1.57075" xyz="0 0 1.05"/>
    <parent link="base_footprint"/>
    <child link="herb_frame"/>
  </joint>
  <joint name="frame_to_base" type="fixed">
    <origin rpy="0 0 3.141592" xyz="0 -0.074086 -1.101244"/>
    <parent link="herb_frame"/>
    <child link="neobotix_base"/>
  </joint>
  <!-- Dummy link to match ROS conventions. -->
  <link name="base_link">
    <inertial>
      <mass value="0.001"/>
      <inertia ixx="0" ixy="0" ixz="0" iyy="0" iyz="0" izz="0"/>
    </inertial>
  </link>
  <joint name="base_link" type="fixed">
    <origin rpy="0 0 0" xyz="0 0 0"/>
    <parent link="neobotix_base"/>
    <child link="base_link"/>
  </joint>
  
  <!-- Left arm -->
  <link name="/left/wam_base">
    <visual>
      <origin rpy="0 0 0" xyz="0 0 0"/>
      <geometry>
        <mesh filename="package://herb_description/meshes/wam/wam_base.dae"/>
      </geometry>
      <material name="">
        <color rgba="0.792156862745098 0.819607843137255 0.933333333333333 1"/>
      </material>
    </visual>
    <inertial>
      <origin rpy="0 0 0" xyz="0.21556578 0.26189039 0.34533511"/>
      <mass value="9.97059584"/>
      <inertia ixx="0.10916849" ixy="0.00640270" ixz="0.02557874" iyx="0.00000000" iyy="0.18294303" iyz="0.00161433" izx="0.00000000" izy="0.00000000" izz="0.11760385"/>
    </inertial>
    <collision>
      <geometry>
        <mesh filename="package://herb_description/meshes/wam/wam_base_collision.STL"/>
      </geometry>
    </collision>
  </link>
  <link name="/left/wam1">
    <visual>
      <origin rpy="0 0 0" xyz="0 0 0"/>
      <geometry>
        <mesh filename="package://herb_description/meshes/wam/wam1.dae"/>
      </geometry>
      <material name="">
        <color rgba="0.792156862745098 0.819607843137255 0.933333333333333 1"/>
      </material>
    </visual>
    <inertial>
      <origin rpy="-1.570796 0 0" xyz="-0.004434 -0.000665 -0.121890"/>
      <mass value="10.76768767"/>
      <inertia ixx="0.13488033" ixy="-0.00213041" ixz="-0.00012485" iyx="0.00000000" iyy="0.11328369" iyz="0.00068555" izx="0.00000000" izy="0.00000000" izz="0.09046330"/>
    </inertial>
    <collision>
      <geometry>
        <mesh filename="package://herb_description/meshes/wam/wam1_collision.STL"/>
      </geometry>
    </collision>
  </link>
  <joint name="/left/j1" type="revolute">
    <origin rpy="-1.1127E-16 0 0" xyz="0.22 0.14 0.346"/>
    <parent link="/left/wam_base"/>
    <child link="/left/wam1"/>
    <axis xyz="0 0 1"/>
    <!-- HERB's J1 joints are modified to have a +180 degree offset. -->
    <limit effort="1.8" lower="0.54159265359" upper="5.74159265359" velocity="0.75"/>
  </joint>
  <joint name="/left/wam_mount" type="fixed">
    <origin rpy="0 -1.57075 -1.57075" xyz="-0.355924 0.005376 -0.357421"/>
    <parent link="herb_frame"/>
    <child link="/left/wam_base"/>
  </joint>
</robot>
